<?xml version="1.0"?>
<robot xmlns:xacro="http://www.ros.org/wiki/xacro" name="wheel">
    <xacro:include filename="$(find ros_robot_description)/urdf/properties.xacro"/>
    <xacro:macro name="wheel" params="name translation rotation parent">

        <gazebo>
            <plugin name="gazebo_ros_control" filename="libgazebo_ros_control.so">
                <robotNamespace>/my_robot</robotNamespace>
            </plugin>
        </gazebo>

        <link name="${name}_wheel">
            <inertial>
                <origin xyz="${WHEEL_COM}" rpy="0.0 0.0 0.0"/>
                <mass value="${WHEEL_M}"/>
                <inertia ixx="${WHEEL_Ixx}" ixy="${WHEEL_Ixy}" ixz="${WHEEL_Ixz}" iyy="${WHEEL_Iyy}" iyz="${WHEEL_Iyz}" izz="${WHEEL_Izz}"/>
            </inertial>
            <visual>
                <origin xyz="0.0 0.0 0.0" rpy="${PI / 2} 0.0 0.0"/>
                <geometry>
                    <cylinder radius="${WHEEL_RADIUS}" length="0.02"/>
                </geometry>
            </visual>
            <collision>
                <origin xyz="0.0 0.0 0.0" rpy="${PI / 2} 0.0 0.0"/>
                <geometry>
                    <cylinder radius="${WHEEL_RADIUS}" length="0.02"/>
                </geometry>
            </collision>
        </link>

        <gazebo reference="${name}_wheel">
            <mu1>1</mu1>
            <mu2>1</mu2>
            <material>Gazebo/Black</material>
        </gazebo>

        <joint name="${name}_wheel_joint" type="continuous">
            <origin xyz="${translation}" rpy="${rotation}"/>
            <parent link="${parent}"/>
            <child link="${name}_wheel"/>
            <axis xyz="0.0 1.0 0.0"/>
            <limit lower="0.0" upper="0.0" effort="${U_MAX}" velocity="${V_MAX}"/>
            <dynamics damping="${WHEEL_JOINT_DAMP}" friction="0.0"/>
            <!--<limit lower="0.0" upper="0.0" effort="0.0" velocity="0.0"/>-->
        </joint>
        
        <!--
        <transmission name="${name}_wheel_trans">
            <type>transmission_interface/SimpleTransmission</type>
            <joint name="${name}_wheel_joint">
                <hardwareInterface>hardware_interface/EffortJointInterface</hardwareInterface>
            </joint>
            <actuator name="${name}_wheel_motor">
                <hardwareInterface>hardware_interface/EffortJointInterface</hardwareInterface>
                <mechanicalReduction>1</mechanicalReduction>
            </actuator>
        </transmission>-->

        <!-- plug in differential drive -->
        <gazebo>
        <plugin name="differential_drive_controller" filename="libgazebo_ros_diff_drive.so">

            <updateRate>10</updateRate>

        
            <robotBaseFrame>base_link</robotBaseFrame>
            <leftJoint>left_wheel_joint</leftJoint>
            <rightJoint>right_wheel_joint</rightJoint>
            
        
            <wheelSeparation>0.42</wheelSeparation>
            <wheelDiameter>0.1</wheelDiameter>
            <wheelAcceleration>0.5</wheelAcceleration>
            <wheelTorque>10.0</wheelTorque>

        
            <commandTopic>cmd_vel</commandTopic>
            <odometryTopic>odom</odometryTopic>
            <odometryFrame>odom</odometryFrame>
            <publishTf>1</publishTf>
            <publishWheelJointState>true</publishWheelJointState>
            <legacyMode>false</legacyMode>

        </plugin>

        </gazebo>

    </xacro:macro>
</robot>